Traceback (most recent call last):
  File "/home/ondrej/.conda/envs/python3.7/lib/python3.7/site-packages/jupyter_cache/executors/utils.py", line 56, in single_nb_execution
    record_timing=False,
  File "/home/ondrej/.conda/envs/python3.7/lib/python3.7/site-packages/nbclient/client.py", line 1087, in execute
    return NotebookClient(nb=nb, resources=resources, km=km, **kwargs).execute()
  File "/home/ondrej/.conda/envs/python3.7/lib/python3.7/site-packages/nbclient/util.py", line 74, in wrapped
    return just_run(coro(*args, **kwargs))
  File "/home/ondrej/.conda/envs/python3.7/lib/python3.7/site-packages/nbclient/util.py", line 53, in just_run
    return loop.run_until_complete(coro)
  File "/home/ondrej/.conda/envs/python3.7/lib/python3.7/asyncio/base_events.py", line 584, in run_until_complete
    return future.result()
  File "/home/ondrej/.conda/envs/python3.7/lib/python3.7/site-packages/nbclient/client.py", line 541, in async_execute
    cell, index, execution_count=self.code_cells_executed + 1
  File "/home/ondrej/.conda/envs/python3.7/lib/python3.7/site-packages/nbclient/client.py", line 832, in async_execute_cell
    self._check_raise_for_error(cell, exec_reply)
  File "/home/ondrej/.conda/envs/python3.7/lib/python3.7/site-packages/nbclient/client.py", line 740, in _check_raise_for_error
    raise CellExecutionError.from_cell_and_msg(cell, exec_reply['content'])
nbclient.exceptions.CellExecutionError: An error occurred while executing the following cell:
------------------
df = pd.read_csv(prefix+"../../data/dates.csv")

#print(df)
df["open_date"] = pd.to_datetime(df["open_date"], format="%d/%m/%Y")
df["closed_date"] = pd.to_datetime(df["closed_date"], format="%d/%m/%Y")
df["completed_p_UK"] = df["completed_UK"] /  df["completed_UK"][0]
df["completed_p_BE"] = df["completed_BE"] /  df["completed_BE"][0]
dates = df;

cdf = pd.melt(df, id_vars=["open_date", "session"], value_vars=["completed_p_UK", "completed_p_BE"], var_name="country", value_name="completed")
cdf["country"] = cdf["country"].str.replace('completed_p_', '')
# turn to percentage 
cdf["completed"]  = cdf["completed"] *100



------------------

[0;31m---------------------------------------------------------------------------[0m
[0;31mNameError[0m                                 Traceback (most recent call last)
[0;32m<ipython-input-2-c7920edec9e8>[0m in [0;36m<module>[0;34m[0m
[0;32m----> 1[0;31m [0mdf[0m [0;34m=[0m [0mpd[0m[0;34m.[0m[0mread_csv[0m[0;34m([0m[0mprefix[0m[0;34m+[0m[0;34m"../../data/dates.csv"[0m[0;34m)[0m[0;34m[0m[0;34m[0m[0m
[0m[1;32m      2[0m [0;34m[0m[0m
[1;32m      3[0m [0;31m#print(df)[0m[0;34m[0m[0;34m[0m[0;34m[0m[0m
[1;32m      4[0m [0mdf[0m[0;34m[[0m[0;34m"open_date"[0m[0;34m][0m [0;34m=[0m [0mpd[0m[0;34m.[0m[0mto_datetime[0m[0;34m([0m[0mdf[0m[0;34m[[0m[0;34m"open_date"[0m[0;34m][0m[0;34m,[0m [0mformat[0m[0;34m=[0m[0;34m"%d/%m/%Y"[0m[0;34m)[0m[0;34m[0m[0;34m[0m[0m
[1;32m      5[0m [0mdf[0m[0;34m[[0m[0;34m"closed_date"[0m[0;34m][0m [0;34m=[0m [0mpd[0m[0;34m.[0m[0mto_datetime[0m[0;34m([0m[0mdf[0m[0;34m[[0m[0;34m"closed_date"[0m[0;34m][0m[0;34m,[0m [0mformat[0m[0;34m=[0m[0;34m"%d/%m/%Y"[0m[0;34m)[0m[0;34m[0m[0;34m[0m[0m

[0;31mNameError[0m: name 'prefix' is not defined
NameError: name 'prefix' is not defined

